Workbook

Sheet Sheet1
A1: Customer_ID | B1: Customer_Name | C1: Region | D1: Product_Category | E1: Sales | F1: Quantity | G1: Discount | H1: Order_Date | I1: Profit
A2: CUST019 | B2: James Davis | C2: West | D2: Books | E2: 1036.09 | F2: 4 | G2: 0.2 | H2: 45392 | I2: 331.55
A3: CUST012 | B3: Robert Anderson | C3: West | D3: Clothing | E3: 1101.28 | F3: 3 | G3: 0.2 | H3: 45393 | I3: 440.51
A4: CUST017 | B4: James Taylor | C4: East | D4: Books | E4: 713.34 | F4: 17 | G4: 0 | H4: 45396 | I4: 285.34
A5: CUST005 | B5: Robert Anderson | C5: South | D5: Electronics | E5: 760.93 | F5: 4 | G5: 0.15 | H5: 45396 | I5: 161.7
A6: CUST030 | B6: James Wilson | C6: North | D6: Books | E6: 847 | F6: 12 | G6: 0.2 | H6: 45397 | I6: 271.04
A7: CUST007 | B7: Michael Anderson | C7: North | D7: Furniture | E7: 965.64 | F7: 8 | G7: 0.1 | H7: 45398 | I7: 304.18
A8: CUST001 | B8: Linda Wilson | C8: West | D8: Electronics | E8: 1317.53 | F8: 12 | G8: 0.05 | H8: 45398 | I8: 312.91
A9: CUST026 | B9: Mary Davis | C9: East | D9: Furniture | E9: 1074.47 | F9: 6 | G9: 0.2 | H9: 45401 | I9: 300.85
A10: CUST009 | B10: Linda Jackson | C10: Central | D10: Books | E10: 501.54 | F10: 11 | G10: 0.05 | H10: 45401 | I10: 190.59
A11: CUST010 | B11: David Thomas | C11: Central | D11: Clothing | E11: 737.31 | F11: 2 | G11: 0.05 | H11: 45401 | I11: 350.22
A12: CUST014 | B12: Emma Davis | C12: West | D12: Office Supplies | E12: 1572.82 | F12: 6 | G12: 0.05 | H12: 45402 | I12: 672.38
A13: CUST014 | B13: David Thomas | C13: Central | D13: Books | E13: 1343.13 | F13: 14 | G13: 0.15 | H13: 45404 | I13: 456.66
... A201: CUST016 | B201: David Thomas | C201: South | D201: Clothing | E201: 928.32 | F201: 2 | G201: 0.05 | H201: 45754 | I201: 440.95

Sheet Tasks
A1: 1. Apply conditional formatting to highlight top 10 customers based on total purchase. | G1: 2. Perform WHAT IF Analysis to see impact of changing discount on total profit.
A3: Customer_ID | B3: Sales | G3: Discount | H3: Sales | I3: total sales | J3: Profit | K3: total profit
A4: {=_xlfn.UNIQUE(Sheet1!A2:A201)} -> CUST019 | B4: =SUMIF(Sheet1!A:A,A4,Sheet1!E:E) -> 4640.11 | G4: 0.2 | H4: 1036.09 | I4: =SUM(H4:H203) -> 195217.76 | J4: 331.55 | K4: =SUM(J4:J203) -> 68287.01
A5: CUST012 | B5: =SUMIF(Sheet1!A:A,A5,Sheet1!E:E) -> 8339 | G5: 0.2 | H5: 1101.28 | J5: 440.51
A6: CUST017 | B6: =SUMIF(Sheet1!A:A,A6,Sheet1!E:E) -> 3419.2 | G6: 0 | H6: 713.34 | J6: 285.34 | N6: 0
A7: CUST005 | B7: =SUMIF(Sheet1!A:A,A7,Sheet1!E:E) -> 6666.13 | G7: 0.15 | H7: 760.93 | J7: 161.7
A8: CUST030 | B8: =SUMIF(Sheet1!A:A,A8,Sheet1!E:E) -> 7928.71 | G8: 0.2 | H8: 847 | J8: 271.04 | M8: =K4-(I4*N6) -> 68287.01
A9: CUST007 | B9: =SUMIF(Sheet1!A:A,A9,Sheet1!E:E) -> 9941.88 | G9: 0.1 | H9: 965.64 | J9: 304.18 | L9: 0 | M9: 68287.01
A10: CUST001 | B10: =SUMIF(Sheet1!A:A,A10,Sheet1!E:E) -> 6549.55 | G10: 0.05 | H10: 1317.53 | J10: 312.91 | L10: 0.05 | M10: 58526.122
A11: CUST026 | B11: =SUMIF(Sheet1!A:A,A11,Sheet1!E:E) -> 9371.81 | G11: 0.2 | H11: 1074.47 | J11: 300.85 | L11: 0.1 | M11: 48765.234
A12: CUST009 | B12: =SUMIF(Sheet1!A:A,A12,Sheet1!E:E) -> 6505.2 | G12: 0.05 | H12: 501.54 | J12: 190.59 | L12: 0.15 | M12: 39004.346
A13: CUST010 | B13: =SUMIF(Sheet1!A:A,A13,Sheet1!E:E) -> 4259.22 | G13: 0.05 | H13: 737.31 | J13: 350.22 | L13: 0.2 | M13: 29243.458
A14: CUST014 | B14: =SUMIF(Sheet1!A:A,A14,Sheet1!E:E) -> 6729.89 | G14: 0.05 | H14: 1572.82 | J14: 672.38
A15: CUST023 | B15: =SUMIF(Sheet1!A:A,A15,Sheet1!E:E) -> 5913.68 | G15: 0.15 | H15: 1343.13 | J15: 456.66
A16: CUST029 | B16: =SUMIF(Sheet1!A:A,A16,Sheet1!E:E) -> 5779.05 | G16: 0.05 | H16: 1191.58 | J16: 452.8
A17: CUST008 | B17: =SUMIF(Sheet1!A:A,A17,Sheet1!E:E) -> 9760.8 | G17: 0.05 | H17: 822.28 | J17: 273.41
A18: CUST006 | B18: =SUMIF(Sheet1!A:A,A18,Sheet1!E:E) -> 2699.75 | G18: 0.15 | H18: 521.67 | J18: 155.2
A19: CUST022 | B19: =SUMIF(Sheet1!A:A,A19,Sheet1!E:E) -> 4418.28 | G19: 0.2 | H19: 1502.93 | J19: 300.59
A20: CUST028 | B20: =SUMIF(Sheet1!A:A,A20,Sheet1!E:E) -> 10293.87 | G20: 0.15 | H20: 877.58 | J20: 298.38
A21: CUST025 | B21: =SUMIF(Sheet1!A:A,A21,Sheet1!E:E) -> 6716.52 | G21: 0.2 | H21: 636.7 | J21: 203.74
A22: CUST021 | B22: =SUMIF(Sheet1!A:A,A22,Sheet1!E:E) -> 8740.18 | G22: 0.2 | H22: 1506.14 | J22: 481.96
A23: CUST015 | B23: =SUMIF(Sheet1!A:A,A23,Sheet1!E:E) -> 11611.06 | G23: 0 | H23: 645.02 | J23: 161.26
A24: CUST016 | B24: =SUMIF(Sheet1!A:A,A24,Sheet1!E:E) -> 3369.17 | G24: 0 | H24: 953.3 | J24: 476.65
A25: CUST011 | B25: =SUMIF(Sheet1!A:A,A25,Sheet1!E:E) -> 3762.29 | G25: 0.15 | H25: 388.56 | J25: 82.57
... A33: CUST018 | B33: =SUMIF(Sheet1!A:A,A33,Sheet1!E:E) -> 4951.89 | G33: 0.2 | H33: 801.21 | J33: 160.24
G34: 0.1 | H34: 1450.71 | J34: 326.41
G35: 0.05 | H35: 1023.21 | J35: 388.82
G36: 0.15 | H36: 853.72 | J36: 253.98
G37: 0.1 | H37: 967.89 | J37: 217.78
G38: 0.05 | H38: 1200.9 | J38: 513.38
G39: 0.2 | H39: 472.38 | J39: 151.16
G40: 0.05 | H40: 840.92 | J40: 359.49
G41: 0.05 | H41: 1410.06 | J41: 468.84
G42: 0.15 | H42: 773.09 | J42: 229.99
G43: 0.15 | H43: 580.43 | J43: 197.35
G44: 0.1 | H44: 1151.21 | J44: 414.44
G45: 0.2 | H45: 1025.98 | J45: 369.35
... G203: 0.05 | H203: 928.32 | J203: 440.95

Sheet data analysis
A1: 3. Use Data Analysis Toolpak to run Linear Regression (Profit vs Sales). | L1: 6. Create a timestamp column using NOW().
N2: Timestamp
N3: =NOW() -> 46318.351
A4: SUMMARY OUTPUT
A6: Regression Statistics
A7: Multiple R | B7: 0.77340306
A8: R Square | B8: 0.5981523
A9: Adjusted R Square | B9: 0.59612277
A10: Standard Error | B10: 86.281231
A11: Observations | B11: 200
A13: ANOVA
B14: df | C14: SS | D14: MS | E14: F | F14: Significance F
A15: Regression | B15: 1 | C15: 2194058.2 | D15: 2194058.2 | E15: 294.72398 | F15: 4.6269368e-41
A16: Residual | B16: 198 | C16: 1474001.2 | D16: 7444.4507
A17: Total | B17: 199 | C17: 3668059.4
B19: Coefficients | C19: Standard Error | D19: t Stat | E19: P-value | F19: Lower 95% | G19: Upper 95% | H19: Lower 95.0% | I19: Upper 95.0%
A20: Intercept | B20: -1.0315505 | C20: 20.860617 | D20: -0.049449663 | E20: 0.9606108 | F20: -42.169052 | G20: 40.105951 | H20: -42.169052 | I20: 40.105951
A21: Sales | B21: 0.35085599 | C21: 0.020437189 | D21: 17.167527 | E21: 4.6269368e-41 | F21: 0.3105535 | G21: 0.39115848 | H21: 0.3105535 | I21: 0.39115848
A24: 4. Use 'Descriptive Statistics' from Analysis Toolpak on the dataset.
A25: Sales | C25: Quantity | E25: Discount | G25: Order_Date | I25: Profit
A27: Mean | B27: 976.0888 | C27: Mean | D27: 9.995 | E27: Mean | F27: 0.09725 | G27: Mean | H27: 45564.145 | I27: Mean | J27: 341.43505
A28: Standard Error | B28: 21.16185 | C28: Standard Error | D28: 0.39927683 | E28: Standard Error | F28: 0.0051142414 | G28: Standard Error | H28: 7.9187977 | I28: Standard Error | J28: 9.6001196
A29: Median | B29: 976.72 | C29: Median | D29: 10 | E29: Median | F29: 0.1 | G29: Median | H29: 45564.5 | I29: Median | J29: 332.255
A30: Mode | B30: #N/A | C30: Mode | D30: 8 | E30: Mode | F30: 0.2 | G30: Mode | H30: 45429 | I30: Mode | J30: #N/A
A31: Standard Deviation | B31: 299.27376 | C31: Standard Deviation | D31: 5.646627 | E31: Standard Deviation | F31: 0.072326295 | G31: Standard Deviation | H31: 111.98871 | I31: Standard Deviation | J31: 135.76619
A32: Sample Variance | B32: 89564.783 | C32: Sample Variance | D32: 31.884397 | E32: Sample Variance | F32: 0.005231093 | G32: Sample Variance | H32: 12541.471 | I32: Sample Variance | J32: 18432.459
A33: Kurtosis | B33: -0.088595232 | C33: Kurtosis | D33: -1.2091054 | E33: Kurtosis | F33: -1.3257012 | G33: Kurtosis | H33: -1.2820132 | I33: Kurtosis | J33: 0.26450644
A34: Skewness | B34: 0.14685797 | C34: Skewness | D34: 0.060845864 | E34: Skewness | F34: 0.096827386 | G34: Skewness | H34: 0.060697356 | I34: Skewness | J34: 0.57339636
A35: Range | B35: 1665.15 | C35: Range | D35: 18 | E35: Range | F35: 0.2 | G35: Range | H35: 362 | I35: Range | J35: 704.83
A36: Minimum | B36: 258.51 | C36: Minimum | D36: 1 | E36: Minimum | F36: 0 | G36: Minimum | H36: 45392 | I36: Minimum | J36: 64.63
A37: Maximum | B37: 1923.66 | C37: Maximum | D37: 19 | E37: Maximum | F37: 0.2 | G37: Maximum | H37: 45754 | I37: Maximum | J37: 769.46
A38: Sum | B38: 195217.76 | C38: Sum | D38: 1999 | E38: Sum | F38: 19.45 | G38: Sum | H38: 9112829 | I38: Sum | J38: 68287.01
A39: Count | B39: 200 | C39: Count | D39: 200 | E39: Count | F39: 200 | G39: Count | H39: 200 | I39: Count | J39: 200
A41: 5. Add up/down arrows on monthly sales growth.
A42: Row Labels | B42: Sum of Sales
A43: 2024 | B43: 145429.36 | C43: =(B44-B43)/B43 -> -0.86914637
A44: Apr | B44: 19029.96 | C44: =(B45-B44)/B44 -> -0.027463011
A45: May | B45: 18507.34 | C45: =(B46-B45)/B45 -> 0.090783981
A46: Jun | B46: 20187.51 | C46: =(B47-B46)/B46 -> -0.42493948
A47: Jul | B47: 11609.04 | C47: =(B48-B47)/B47 -> -0.13070331
...

Sheet highvaluecus
A1: Customer_ID | B1: Customer_Name | C1: Region | D1: Product_Category | E1: Sales | F1: Quantity | G1: Discount | H1: Order_Date | I1: Profit | J1: highest purchase | L1: =MAX(E2:E201) -> 1923.66
A2: CUST019 | B2: James Davis | C2: West | D2: Books | E2: 1036.09 | F2: 4 | G2: 0.2 | H2: 45392 | I2: 331.55 | J2: high-value customer | L2: =INDEX(B2:B201, MATCH(L1, E2:E201, 0)) -> James Wilson
A3: CUST012 | B3: Robert Anderson | C3: West | D3: Clothing | E3: 1101.28 | F3: 3 | G3: 0.2 | H3: 45393 | I3: 440.51 | J3: customerid | L3: =INDEX(A2:A201, MATCH(L1, E2:E201, 0)) -> CUST015
A4: CUST017 | B4: James Taylor | C4: East | D4: Books | E4: 713.34 | F4: 17 | G4: 0 | H4: 45396 | I4: 285.34
A5: CUST005 | B5: Robert Anderson | C5: South | D5: Electronics | E5: 760.93 | F5: 4 | G5: 0.15 | H5: 45396 | I5: 161.7
A6: CUST030 | B6: James Wilson | C6: North | D6: Books | E6: 847 | F6: 12 | G6: 0.2 | H6: 45397 | I6: 271.04
A7: CUST007 | B7: Michael Anderson | C7: North | D7: Furniture | E7: 965.64 | F7: 8 | G7: 0.1 | H7: 45398 | I7: 304.18
A8: CUST001 | B8: Linda Wilson | C8: West | D8: Electronics | E8: 1317.53 | F8: 12 | G8: 0.05 | H8: 45398 | I8: 312.91
A9: CUST026 | B9: Mary Davis | C9: East | D9: Furniture | E9: 1074.47 | F9: 6 | G9: 0.2 | H9: 45401 | I9: 300.85
A10: CUST009 | B10: Linda Jackson | C10: Central | D10: Books | E10: 501.54 | F10: 11 | G10: 0.05 | H10: 45401 | I10: 190.59
A11: CUST010 | B11: David Thomas | C11: Central | D11: Clothing | E11: 737.31 | F11: 2 | G11: 0.05 | H11: 45401 | I11: 350.22
A12: CUST014 | B12: Emma Davis | C12: West | D12: Office Supplies | E12: 1572.82 | F12: 6 | G12: 0.05 | H12: 45402 | I12: 672.38
A13: CUST014 | B13: David Thomas | C13: Central | D13: Books | E13: 1343.13 | F13: 14 | G13: 0.15 | H13: 45404 | I13: 456.66
A14: CUST007 | B14: Michael Anderson | C14: Central | D14: Books | E14: 1191.58 | F14: 14 | G14: 0.05 | H14: 45406 | I14: 452.8
A15: CUST023 | B15: Robert Anderson | C15: West | D15: Furniture | E15: 822.28 | F15: 7 | G15: 0.05 | H15: 45406 | I15: 273.41
... A201: CUST016 | B201: David Thomas | C201: South | D201: Clothing | E201: 928.32 | F201: 2 | G201: 0.05 | H201: 45754 | I201: 440.95

Sheet totalsales
A1: 8. Create Pivot Table to analyze total sales by region and product. | E1: 9. Create bar, line, and pie charts to visualize KPIs. | P1: Line Chart
M2: Row Labels | N2: Sum of Sales
A3: Row Labels | B3: Sum of Sales | F3: Bar Chart | M3: Jan | N3: 14914.65
A4: Central | B4: 43468.33 | M4: Feb | N4: 14006.36
A5: Books | B5: 11297.15 | M5: Mar | N5: 17655.22
A6: Clothing | B6: 12200.26 | M6: Apr | N6: 22242.13
A7: Electronics | B7: 6621.24 | M7: May | N7: 18507.34
A8: Furniture | B8: 4876.96 | M8: Jun | N8: 20187.51
A9: Office Supplies | B9: 8472.72 | M9: Jul | N9: 11609.04
A10: East | B10: 32441.64 | M10: Aug | N10: 10091.7
A11: Books | B11: 11389.09 | M11: Sep | N11: 20533.5
A12: Clothing | B12: 2401.45 | M12: Oct | N12: 14215.24
A13: Electronics | B13: 2869.54 | M13: Nov | N13: 20135.03
A14: Furniture | B14: 7592.34 | M14: Dec | N14: 11120.04
A15: Office Supplies | B15: 8189.22 | M15: Grand Total | N15: 195217.76
A16: North | B16: 34975.42
A17: Books | B17: 8037.01
A18: Clothing | B18: 8422.82
A19: Electronics | B19: 8191.71
A20: Furniture | B20: 6978.08
A21: Office Supplies | B21: 3345.8
A22: South | B22: 40248.79 | E22: Row Labels | F22: Sum of Sales | J22: Pie Chart
A23: Books | B23: 9588.04 | E23: Central | F23: 43468.33
A24: Clothing | B24: 8393.63 | E24: East | F24: 32441.64
A25: Electronics | B25: 11989.07 | E25: North | F25: 34975.42
A26: Furniture | B26: 7982.73 | E26: South | F26: 40248.79
A27: Office Supplies | B27: 2295.32 | E27: West | F27: 44083.58
A28: West | B28: 44083.58 | E28: Grand Total | F28: 195217.76
A29: Books | B29: 6691.17
A30: Clothing | B30: 10509.43
A31: Electronics | B31: 11372.44
A32: Furniture | B32: 9182.78
A33: Office Supplies | B33: 6327.76
A34: Grand Total | B34: 195217.76

Sheet dashboard summary
A1: EXECUTIVE DASHBOARD INSIGHTS & KEY PERFORMANCE INDICATORS
A3: KPI Summary Table
A4: Metric | B4: Key Finding | C4: Details / Revenue Impact
A5: Top Performing Region | B5: West Region | C5: Total Sales: $44,083.58 (Highest Share)
A6: Second Best Region | B6: Central Region | C6: Total Sales: $43,468.33
A7: Peak Sales Months | B7: April & September | C7: Highest monthly surge in sales trend
A8: Lowest Sales Month | B8: August | C8: Dip observed at $10,031.70
A10: Detailed Business Insights (Detailed Block)
